Workbook

Sheet Gerenciamento IH
A1: Data de abertura | B1: OS | C1: Nome do Cliente | D1: Modelo da Condensadora / Evaporadora | E1: N° de série | F1: TAT | G1: Peça Necessária? | H1: Agendado? | I1: Data da Visita | J1: Necessita Retorno? | K1: Peça Necessária para Retorno? | L1: Retorno Agendado? | M1: Data da 2° Visita | N1: Reparo finalizado? | O1: Toda Documentação está disponível? | P1: Necessário VOID? | Q1: SAW ( Extra Man ) | R1: SAW ( KM ) | S1: Data da Finalização OS | T1: Analista | U1: N° GA (SÓ PARA AM) | V1: Observações
A2: =IFERROR(__xludf.DUMMYFUNCTION("IFERROR(TO_TEXT(INDEX(Base!E:E, MATCH(B2, Base!A:A, 0))), ""mm.dd.yyyy"") "),"11.10.2025") -> 11.10.2025 | B2: 4174445115 | C2: {=IFERROR(INDEX(Base!I:I,MATCH(B2,Base!A:A,0)),"Nome do Cliente")} -> MARIO GOMES DA SILVA | D2: {=IFERROR(INDEX(Base!G:G,MATCH(B2,Base!A:A,0)),"Modelo da Cond.")} -> AC018DN1DKG/AZ | E2: {=IFERROR(INDEX(Base!H:H,MATCH(B2,Base!A:A,0)),"N° Serial")} -> 0309PXAY700069B | F2: =INT(TODAY() - DATE(RIGHT(A2,4), LEFT(A2,2), MID(A2,4,2))) -> 160 | G2: Não | H2: TRUE | I2: 45982 | J2: Sim | K2: Sim, solicitada | L2: TRUE | M2: 06/01/2026 e 08/04/2026 | N2: FALSE | V2: 1ª kaynã - 2ª visita éder - Terá mais uma visita, necessário peça, 3°- visita éder = delton = levar motor de passo 2 1 placa 1 moldura 1 aleta
A3: =IFERROR(__xludf.DUMMYFUNCTION("IFERROR(TO_TEXT(INDEX(Base!E:E, MATCH(B3, Base!A:A, 0))), ""mm.dd.yyyy"") "),"12.01.2025") -> 12.01.2025 | B3: 4174601418 | C3: {=IFERROR(INDEX(Base!I:I,MATCH(B3,Base!A:A,0)),"Nome do Cliente")} -> Bruno Henrique Dannas Pelogia | D3: {=IFERROR(INDEX(Base!G:G,MATCH(B3,Base!A:A,0)),"Modelo da Cond.")} -> AJ050AXJ2KH/AZ | E3: {=IFERROR(INDEX(Base!H:H,MATCH(B3,Base!A:A,0)),"N° Serial")} -> 02TGPXBX200299V | F3: =INT(TODAY() - DATE(RIGHT(A3,4), LEFT(A3,2), MID(A3,4,2))) -> 139 | G3: Não | H3: TRUE | I3: 46029 | J3: Sim | K3: Sim, em estoque | L3: TRUE | M3: 46136 | N3: FALSE | V3: Eder
A4: =IFERROR(__xludf.DUMMYFUNCTION("IFERROR(TO_TEXT(INDEX(Base!E:E, MATCH(B4, Base!A:A, 0))), ""mm.dd.yyyy"") "),"02.26.2026") -> 02.26.2026 | B4: 4175256827 | C4: {=IFERROR(INDEX(Base!I:I,MATCH(B4,Base!A:A,0)),"Nome do Cliente")} -> Lorena De Souza cordeiro | D4: {=IFERROR(INDEX(Base!G:G,MATCH(B4,Base!A:A,0)),"Modelo da Cond.")} -> AM070TXMDKH/AZ | E4: {=IFERROR(INDEX(Base!H:H,MATCH(B4,Base!A:A,0)),"N° Serial")} -> 0VMXPAOT700052B | F4: =INT(TODAY() - DATE(RIGHT(A4,4), LEFT(A4,2), MID(A4,4,2))) -> 52 | G4: Sim, em estoque | H4: TRUE | I4: 46111 | J4: Não | K4: Não | L4: FALSE | N4: TRUE | O4: Sim | P4: Não | Q4: Realizado, não lançado | R4: Realizado, não lançado | V4: OS finalizada, necessário adicionar sintomas, extraman e KM
A5: =IFERROR(__xludf.DUMMYFUNCTION("IFERROR(TO_TEXT(INDEX(Base!E:E, MATCH(B5, Base!A:A, 0))), ""mm.dd.yyyy"") "),"12.19.2025") -> 12.19.2025 | B5: 4174748994 | C5: {=IFERROR(INDEX(Base!I:I,MATCH(B5,Base!A:A,0)),"Nome do Cliente")} -> Eliane Vignatti Avancini | D5: {=IFERROR(INDEX(Base!G:G,MATCH(B5,Base!A:A,0)),"Modelo da Cond.")} -> AC048TN4DKC/AZ | E5: {=IFERROR(INDEX(Base!H:H,MATCH(B5,Base!A:A,0)),"N° Serial")} -> BF09P3HW800039W | F5: =INT(TODAY() - DATE(RIGHT(A5,4), LEFT(A5,2), MID(A5,4,2))) -> 121 | G5: Não | H5: TRUE | I5: 46041 | J5: Sim | K5: Sim, não solicitada | L5: TRUE | M5: 46126 | N5: FALSE | V5: Anderson 1° visita. 2° Guilherme, será necessário retorno com mais peças.
A6: =IFERROR(__xludf.DUMMYFUNCTION("IFERROR(TO_TEXT(INDEX(Base!E:E, MATCH(B6, Base!A:A, 0))), ""mm.dd.yyyy"") "),"12.17.2025") -> 12.17.2025 | B6: 4174734388 | C6: {=IFERROR(INDEX(Base!I:I,MATCH(B6,Base!A:A,0)),"Nome do Cliente")} -> Endrigo Rampaso | D6: {=IFERROR(INDEX(Base!G:G,MATCH(B6,Base!A:A,0)),"Modelo da Cond.")} -> AM028TNVDKH/EU | E6: {=IFERROR(INDEX(Base!H:H,MATCH(B6,Base!A:A,0)),"N° Serial")} -> 0HG6PDCX900064A | F6: =INT(TODAY() - DATE(RIGHT(A6,4), LEFT(A6,2), MID(A6,4,2))) -> 123 | G6: Sim, em estoque | H6: TRUE | I6: 46017 | J6: Não | K6: Não | L6: FALSE | N6: TRUE | O6: Sim | Q6: Realizado, não lançado | R6: Realizado, não lançado | U6: 1253462670 | V6: Subir Extraman e KM
A7: =IFERROR(__xludf.DUMMYFUNCTION("IFERROR(TO_TEXT(INDEX(Base!E:E, MATCH(B7, Base!A:A, 0))), ""mm.dd.yyyy"") "),"01.05.2026") -> 01.05.2026 | B7: 4174846790 | C7: {=IFERROR(INDEX(Base!I:I,MATCH(B7,Base!A:A,0)),"Nome do Cliente")} -> Fernando Romeu Miassi | D7: {=IFERROR(INDEX(Base!G:G,MATCH(B7,Base!A:A,0)),"Modelo da Cond.")} -> AM036TNVDKH/EU | E7: {=IFERROR(INDEX(Base!H:H,MATCH(B7,Base!A:A,0)),"N° Serial")} -> 0HG7PDAW900052X | F7: =INT(TODAY() - DATE(RIGHT(A7,4), LEFT(A7,2), MID(A7,4,2))) -> 104 | G7: Não | H7: TRUE | I7: 46034 | J7: Sim | K7: Sim, em estoque | L7: TRUE | M7: 46084 | N7: TRUE | O7: Sim | P7: Não | Q7: Realizado, não lançado | R7: Realizado, não lançado | V7: Subir Extraman e KM
A8: =IFERROR(__xludf.DUMMYFUNCTION("IFERROR(TO_TEXT(INDEX(Base!E:E, MATCH(B8, Base!A:A, 0))), ""mm.dd.yyyy"") "),"01.07.2026") -> 01.07.2026 | B8: 4174866947 | C8: {=IFERROR(INDEX(Base!I:I,MATCH(B8,Base!A:A,0)),"Nome do Cliente")} -> Sidnei Dos Reis Lopes | D8: {=IFERROR(INDEX(Base!G:G,MATCH(B8,Base!A:A,0)),"Modelo da Cond.")} -> AC018DN1DKG/AZ | E8: {=IFERROR(INDEX(Base!H:H,MATCH(B8,Base!A:A,0)),"N° Serial")} -> 0309PXAY400025P | F8: =INT(TODAY() - DATE(RIGHT(A8,4), LEFT(A8,2), MID(A8,4,2))) -> 102 | G8: Sim, em estoque | H8: FALSE | L8: FALSE | N8: FALSE | V8: Cliente resolveu por conta, como finalizar?
A9: =IFERROR(__xludf.DUMMYFUNCTION("IFERROR(TO_TEXT(INDEX(Base!E:E, MATCH(B9, Base!A:A, 0))), ""mm.dd.yyyy"") "),"01.09.2026") -> 01.09.2026 | B9: 4174886626 | C9: {=IFERROR(INDEX(Base!I:I,MATCH(B9,Base!A:A,0)),"Nome do Cliente")} -> VICENTE DE PAULA CRUZ | D9: {=IFERROR(INDEX(Base!G:G,MATCH(B9,Base!A:A,0)),"Modelo da Cond.")} -> MXD-A64K100E | E9: {=IFERROR(INDEX(Base!H:H,MATCH(B9,Base!A:A,0)),"N° Serial")} -> M1502O66X610122 | F9: =INT(TODAY() - DATE(RIGHT(A9,4), LEFT(A9,2), MID(A9,4,2))) -> 100 | G9: Sim, em estoque | H9: TRUE | I9: 46078 | J9: Não | K9: Não | L9: FALSE | N9: TRUE | O9: Não | P9: Não | Q9: Não iniciado | R9: Realizado e lançado | V9: César, verificar com o emerson
A10: =IFERROR(__xludf.DUMMYFUNCTION("IFERROR(TO_TEXT(INDEX(Base!E:E, MATCH(B10, Base!A:A, 0))), ""mm.dd.yyyy"") "),"01.16.2026") -> 01.16.2026 | B10: 4174946607 | C10: {=IFERROR(INDEX(Base!I:I,MATCH(B10,Base!A:A,0)),"Nome do Cliente")} -> COMERCIAL PROTON LIMITADA | D10: {=IFERROR(INDEX(Base!G:G,MATCH(B10,Base!A:A,0)),"Modelo da Cond.")} -> AM170TN4DKH/EA | E10: {=IFERROR(INDEX(Base!H:H,MATCH(B10,Base!A:A,0)),"N° Serial")} -> M000 | F10: =INT(TODAY() - DATE(RIGHT(A10,4), LEFT(A10,2), MID(A10,4,2))) -> 93 | G10: Sim, não solicitada | H10: FALSE | L10: FALSE | N10: FALSE
A11: =IFERROR(__xludf.DUMMYFUNCTION("IFERROR(TO_TEXT(INDEX(Base!E:E, MATCH(B11, Base!A:A, 0))), ""mm.dd.yyyy"") "),"01.14.2026") -> 01.14.2026 | B11: 4174925640 | C11: {=IFERROR(INDEX(Base!I:I,MATCH(B11,Base!A:A,0)),"Nome do Cliente")} -> Thiago Nascimento Pontes | D11: {=IFERROR(INDEX(Base!G:G,MATCH(B11,Base!A:A,0)),"Modelo da Cond.")} -> AJ100DXJ5KH/AZ | E11: {=IFERROR(INDEX(Base!H:H,MATCH(B11,Base!A:A,0)),"N° Serial")} -> 0344PXBY500159H | F11: =INT(TODAY() - DATE(RIGHT(A11,4), LEFT(A11,2), MID(A11,4,2))) -> 95 | G11: Não | H11: TRUE | I11: 46085 | J11: Sim | K11: Sim, não solicitada | L11: TRUE | M11: 46129 | N11: FALSE | V11: 1a. visita Henrique, 2º visita fausto, necesario mais um retorno com peça
A12: =IFERROR(__xludf.DUMMYFUNCTION("IFERROR(TO_TEXT(INDEX(Base!E:E, MATCH(B12, Base!A:A, 0))), ""mm.dd.yyyy"") "),"01.14.2026") -> 01.14.2026 | B12: 4174925699 | C12: {=IFERROR(INDEX(Base!I:I,MATCH(B12,Base!A:A,0)),"Nome do Cliente")} -> Richard Frank | D12: {=IFERROR(INDEX(Base!G:G,MATCH(B12,Base!A:A,0)),"Modelo da Cond.")} -> AJ025ANAPKH2AZ | E12: {=IFERROR(INDEX(Base!H:H,MATCH(B12,Base!A:A,0)),"N° Serial")} -> 0321PXCXA01720X | F12: =INT(TODAY() - DATE(RIGHT(A12,4), LEFT(A12,2), MID(A12,4,2))) -> 95 | G12: Sim, não solicitada | H12: FALSE | L12: FALSE | N12: FALSE
A13: =IFERROR(__xludf.DUMMYFUNCTION("IFERROR(TO_TEXT(INDEX(Base!E:E, MATCH(B13, Base!A:A, 0))), ""mm.dd.yyyy"") "),"01.16.2026") -> 01.16.2026 | B13: 4174947209 | C13: {=IFERROR(INDEX(Base!I:I,MATCH(B13,Base!A:A,0)),"Nome do Cliente")} -> Mathias Braga | D13: {=IFERROR(INDEX(Base!G:G,MATCH(B13,Base!A:A,0)),"Modelo da Cond.")} -> AJ035ANAPKH2AZ | E13: {=IFERROR(INDEX(Base!H:H,MATCH(B13,Base!A:A,0)),"N° Serial")} -> M000 | F13: =INT(TODAY() - DATE(RIGHT(A13,4), LEFT(A13,2), MID(A13,4,2))) -> 93 | H13: FALSE | L13: FALSE | N13: FALSE
A14: =IFERROR(__xludf.DUMMYFUNCTION("IFERROR(TO_TEXT(INDEX(Base!E:E, MATCH(B14, Base!A:A, 0))), ""mm.dd.yyyy"") "),"01.19.2026") -> 01.19.2026 | B14: 4174960583 | C14: {=IFERROR(INDEX(Base!I:I,MATCH(B14,Base!A:A,0)),"Nome do Cliente")} -> William Robert Nahra Filho | D14: {=IFERROR(INDEX(Base!G:G,MATCH(B14,Base!A:A,0)),"Modelo da Cond.")} -> AC024DN4DKG/AZ | E14: {=IFERROR(INDEX(Base!H:H,MATCH(B14,Base!A:A,0)),"N° Serial")} -> 030FPXAX200036P | F14: =INT(TODAY() - DATE(RIGHT(A14,4), LEFT(A14,2), MID(A14,4,2))) -> 90 | G14: Sim, solicitada | H14: TRUE | I14: 46129 | J14: Sim | K14: Sim, não solicitada | L14: FALSE | N14: FALSE
A15: =IFERROR(__xludf.DUMMYFUNCTION("IFERROR(TO_TEXT(INDEX(Base!E:E, MATCH(B15, Base!A:A, 0))), ""mm.dd.yyyy"") "),"01.23.2026") -> 01.23.2026 | B15: 4175001531 | C15: {=IFERROR(INDEX(Base!I:I,MATCH(B15,Base!A:A,0)),"Nome do Cliente")} -> Marcos Phaulo Passos Bastos | D15: {=IFERROR(INDEX(Base!G:G,MATCH(B15,Base!A:A,0)),"Modelo da Cond.")} -> AJ080AXJ4KH/AZ | E15: {=IFERROR(INDEX(Base!H:H,MATCH(B15,Base!A:A,0)),"N° Serial")} -> 02TMPXBY100174H | F15: =INT(TODAY() - DATE(RIGHT(A15,4), LEFT(A15,2), MID(A15,4,2))) -> 86 | G15: Não | H15: TRUE | I15: 46055 | J15: Sim | K15: Sim, não solicitada | L15: FALSE | N15: FALSE | V15: 1° Visita - Henrique - Solicitar placas main e sub
A16: =IFERROR(__xludf.DUMMYFUNCTION("IFERROR(TO_TEXT(INDEX(Base!E:E, MATCH(B16, Base!A:A, 0))), ""mm.dd.yyyy"") "),"01.23.2026") -> 01.23.2026 | B16: 4175002599 | C16: {=IFERROR(INDEX(Base!I:I,MATCH(B16,Base!A:A,0)),"Nome do Cliente")} -> Marcos Phaulo Passos Bastos | D16: {=IFERROR(INDEX(Base!G:G,MATCH(B16,Base!A:A,0)),"Modelo da Cond.")} -> AJ080AXJ4KH/AZ | E16: {=IFERROR(INDEX(Base!H:H,MATCH(B16,Base!A:A,0)),"N° Serial")} -> 02TMPXBY100230J | F16: =INT(TODAY() - DATE(RIGHT(A16,4), LEFT(A16,2), MID(A16,4,2))) -> 86 | G16: Não | H16: TRUE | I16: 46055 | J16: Não | K16: Não | L16: FALSE | N16: FALSE | V16: Henrique - OS aberta com nº do S/N de maquina que não precisa de reparo
A17: =IFERROR(__xludf.DUMMYFUNCTION("IFERROR(TO_TEXT(INDEX(Base!E:E, MATCH(B17, Base!A:A, 0))), ""mm.dd.yyyy"") "),"01.27.2026") -> 01.27.2026 | B17: 4175021965 | C17: {=IFERROR(INDEX(Base!I:I,MATCH(B17,Base!A:A,0)),"Nome do Cliente")} -> MARCOS FERREIRA | D17: {=IFERROR(INDEX(Base!G:G,MATCH(B17,Base!A:A,0)),"Modelo da Cond.")} -> AJ050AXJ2KH/AZ | E17: {=IFERROR(INDEX(Base!H:H,MATCH(B17,Base!A:A,0)),"N° Serial")} -> 02TGPXBY700025R | F17: =INT(TODAY() - DATE(RIGHT(A17,4), LEFT(A17,2), MID(A17,4,2))) -> 82 | G17: Não | H17: TRUE | I17: 46080 | J17: Sim | K17: Sim, não solicitada | L17: FALSE | N17: FALSE | V17: Guilherme
A18: =IFERROR(__xludf.DUMMYFUNCTION("IFERROR(TO_TEXT(INDEX(Base!E:E, MATCH(B18, Base!A:A, 0))), ""mm.dd.yyyy"") "),"01.28.2026") -> 01.28.2026 | B18: 4175031844 | C18: {=IFERROR(INDEX(Base!I:I,MATCH(B18,Base!A:A,0)),"Nome do Cliente")} -> Renato Antonio Casagrande | D18: {=IFERROR(INDEX(Base!G:G,MATCH(B18,Base!A:A,0)),"Modelo da Cond.")} -> AC060DN4DKG/AZ | E18: {=IFERROR(INDEX(Base!H:H,MATCH(B18,Base!A:A,0)),"N° Serial")} -> M000 | F18: =INT(TODAY() - DATE(RIGHT(A18,4), LEFT(A18,2), MID(A18,4,2))) -> 81 | G18: Sim, em estoque | H18: FALSE | L18: FALSE | N18: FALSE | O18: Não | Q18: Não iniciado | R18: Não iniciado | V18: Votuporanga, parceiro
A19: =IFERROR(__xludf.DUMMYFUNCTION("IFERROR(TO_TEXT(INDEX(Base!E:E, MATCH(B19, Base!A:A, 0))), ""mm.dd.yyyy"") "),"01.28.2026") -> 01.28.2026 | B19: 4175039234 | C19: {=IFERROR(INDEX(Base!I:I,MATCH(B19,Base!A:A,0)),"Nome do Cliente")} -> ANDRIGO CARNELOSSI | D19: {=IFERROR(INDEX(Base!G:G,MATCH(B19,Base!A:A,0)),"Modelo da Cond.")} -> AJ050AXJ2KH/AZ | E19: {=IFERROR(INDEX(Base!H:H,MATCH(B19,Base!A:A,0)),"N° Serial")} -> 02TGPXDX700082A | F19: =INT(TODAY() - DATE(RIGHT(A19,4), LEFT(A19,2), MID(A19,4,2))) -> 81 | G19: Não | H19: TRUE | I19: 46052 | J19: Não | K19: Não | L19: FALSE | N19: TRUE | O19: Sim | P19: Sim | Q19: Realizado e lançado | R19: Realizado e lançado | V19: 1° Visita - Anderson
A20: =IFERROR(__xludf.DUMMYFUNCTION("IFERROR(TO_TEXT(INDEX(Base!E:E, MATCH(B20, Base!A:A, 0))), ""mm.dd.yyyy"") "),"01.30.2026") -> 01.30.2026 | B20: 4175055471 | C20: {=IFERROR(INDEX(Base!I:I,MATCH(B20,Base!A:A,0)),"Nome do Cliente")} -> Ligia Pereira Hubert | D20: {=IFERROR(INDEX(Base!G:G,MATCH(B20,Base!A:A,0)),"Modelo da Cond.")} -> AJ050AXJ2KH/AZ | E20: {=IFERROR(INDEX(Base!H:H,MATCH(B20,Base!A:A,0)),"N° Serial")} -> 02TGPXBY200032F | F20: =INT(TODAY() - DATE(RIGHT(A20,4), LEFT(A20,2), MID(A20,4,2))) -> 79 | G20: Não | H20: TRUE | I20: 46079 | J20: Não | K20: Não | L20: FALSE | N20: TRUE | O20: Sim | P20: Sim | Q20: Realizado e lançado | R20: Realizado e lançado | V20: Problema no GSPN - Aguardando resposta Samsung
A21: =IFERROR(__xludf.DUMMYFUNCTION("IFERROR(TO_TEXT(INDEX(Base!E:E, MATCH(B21, Base!A:A, 0))), ""mm.dd.yyyy"") "),"01.30.2026") -> 01.30.2026 | B21: 4175055482 | C21: {=IFERROR(INDEX(Base!I:I,MATCH(B21,Base!A:A,0)),"Nome do Cliente")} -> Patrick De Moura Sousa | D21: {=IFERROR(INDEX(Base!G:G,MATCH(B21,Base!A:A,0)),"Modelo da Cond.")} -> AJ050AXJ2KH/AZ | E21: {=IFERROR(INDEX(Base!H:H,MATCH(B21,Base!A:A,0)),"N° Serial")} -> 02TGPXBX100547H | F21: =INT(TODAY() - DATE(RIGHT(A21,4), LEFT(A21,2), MID(A21,4,2))) -> 79 | G21: Não | H21: TRUE | I21: 46076 | J21: Sim | K21: Não | L21: TRUE | M21: 46126 | N21: FALSE | O21: Não | Q21: Não iniciado | R21: Não iniciado | V21: 1° Visita - kaynã, Necessario retorno para retirar a maquina, maquina na base para teste
A22: =IFERROR(__xludf.DUMMYFUNCTION("IFERROR(TO_TEXT(INDEX(Base!E:E, MATCH(B22, Base!A:A, 0))), ""mm.dd.yyyy"") "),"01.30.2026") -> 01.30.2026 | B22: 4175055490 | C22: {=IFERROR(INDEX(Base!I:I,MATCH(B22,Base!A:A,0)),"Nome do Cliente")} -> GIULIA MADEIROS GUIDONI | D22: {=IFERROR(INDEX(Base!G:G,MATCH(B22,Base!A:A,0)),"Modelo da Cond.")} -> AJ100DXJ5KH/AZ | E22: {=IFERROR(INDEX(Base!H:H,MATCH(B22,Base!A:A,0)),"N° Serial")} -> 0344PXBY900196P | F22: =INT(TODAY() - DATE(RIGHT(A22,4), LEFT(A22,2), MID(A22,4,2))) -> 79 | G22: Sim, em estoque | H22: TRUE | I22: 46092 | J22: Sim | K22: Sim, solicitada | L22: FALSE | N22: FALSE | V22: 1a. Visita Guilherme
A23: =IFERROR(__xludf.DUMMYFUNCTION("IFERROR(TO_TEXT(INDEX(Base!E:E, MATCH(B23, Base!A:A, 0))), ""mm.dd.yyyy"") "),"01.30.2026") -> 01.30.2026 | B23: 4175055496 | C23: {=IFERROR(INDEX(Base!I:I,MATCH(B23,Base!A:A,0)),"Nome do Cliente")} -> Luka Marques De Araujo | D23: {=IFERROR(INDEX(Base!G:G,MATCH(B23,Base!A:A,0)),"Modelo da Cond.")} -> AC018DXADKG/AZ | E23: {=IFERROR(INDEX(Base!H:H,MATCH(B23,Base!A:A,0)),"N° Serial")} -> 030DPXBY200141N | F23: =INT(TODAY() - DATE(RIGHT(A23,4), LEFT(A23,2), MID(A23,4,2))) -> 79 | G23: Não | H23: FALSE | L23: FALSE | N23: FALSE
A24: =IFERROR(__xludf.DUMMYFUNCTION("IFERROR(TO_TEXT(INDEX(Base!E:E, MATCH(B24, Base!A:A, 0))), ""mm.dd.yyyy"") "),"02.02.2026") -> 02.02.2026 | B24: 4175068842 | C24: {=IFERROR(INDEX(Base!I:I,MATCH(B24,Base!A:A,0)),"Nome do Cliente")} -> GABRIELA LUCIANO BORRI ARANDA | D24: {=IFERROR(INDEX(Base!G:G,MATCH(B24,Base!A:A,0)),"Modelo da Cond.")} -> AJ100AXJ5KH/AZ | E24: {=IFERROR(INDEX(Base!H:H,MATCH(B24,Base!A:A,0)),"N° Serial")} -> BLK6P3CX400095V | F24: =INT(TODAY() - DATE(RIGHT(A24,4), LEFT(A24,2), MID(A24,4,2))) -> 76 | G24: Não | H24: TRUE | I24: 46078 | J24: Sim | K24: Sim, em estoque | L24: FALSE | N24: FALSE | V24: 1° Visita - Henrique
A25: =IFERROR(__xludf.DUMMYFUNCTION("IFERROR(TO_TEXT(INDEX(Base!E:E, MATCH(B25, Base!A:A, 0))), ""mm.dd.yyyy"") "),"02.02.2026") -> 02.02.2026 | B25: 4175069975 | C25: {=IFERROR(INDEX(Base!I:I,MATCH(B25,Base!A:A,0)),"Nome do Cliente")} -> Jorge Luiz de Castro e Sil | D25: {=IFERROR(INDEX(Base!G:G,MATCH(B25,Base!A:A,0)),"Modelo da Cond.")} -> AJ068AXJ3KH/AZ | E25: {=IFERROR(INDEX(Base!H:H,MATCH(B25,Base!A:A,0)),"N° Serial")} -> 02TKPXBX300204A | F25: =INT(TODAY() - DATE(RIGHT(A25,4), LEFT(A25,2), MID(A25,4,2))) -> 76 | G25: Sim, em estoque | H25: TRUE | I25: 46085 | J25: Não | K25: Não | L25: FALSE | N25: TRUE | O25: Sim | P25: Não | Q25: Realizado e lançado | R25: Realizado e lançado | V25: Ronitti, aguardando evidencias
A26: =IFERROR(__xludf.DUMMYFUNCTION("IFERROR(TO_TEXT(INDEX(Base!E:E, MATCH(B26, Base!A:A, 0))), ""mm.dd.yyyy"") "),"02.04.2026") -> 02.04.2026 | B26: 4175087864 | C26: {=IFERROR(INDEX(Base!I:I,MATCH(B26,Base!A:A,0)),"Nome do Cliente")} -> Marcelo Giovani Bernardino p | D26: {=IFERROR(INDEX(Base!G:G,MATCH(B26,Base!A:A,0)),"Modelo da Cond.")} -> AJ035ANAPKH2AZ | E26: {=IFERROR(INDEX(Base!H:H,MATCH(B26,Base!A:A,0)),"N° Serial")} -> 0322PXCXC00229K | F26: =INT(TODAY() - DATE(RIGHT(A26,4), LEFT(A26,2), MID(A26,4,2))) -> 74 | G26: Não | H26: FALSE | L26: FALSE | N26: FALSE
A27: =IFERROR(__xludf.DUMMYFUNCTION("IFERROR(TO_TEXT(INDEX(Base!E:E, MATCH(B27, Base!A:A, 0))), ""mm.dd.yyyy"") "),"02.04.2026") -> 02.04.2026 | B27: 4175085235 | C27: {=IFERROR(INDEX(Base!I:I,MATCH(B27,Base!A:A,0)),"Nome do Cliente")} -> Vinicius Milhan Hipolito | D27: {=IFERROR(INDEX(Base!G:G,MATCH(B27,Base!A:A,0)),"Modelo da Cond.")} -> AC024DN4DKG/AZ | E27: {=IFERROR(INDEX(Base!H:H,MATCH(B27,Base!A:A,0)),"N° Serial")} -> 030FPXAXA00141N | F27: =INT(TODAY() - DATE(RIGHT(A27,4), LEFT(A27,2), MID(A27,4,2))) -> 74 | G27: Não | H27: TRUE | I27: 46078 | J27: Sim | K27: Sim, em estoque | L27: TRUE | M27: 46127 | N27: TRUE | O27: Não | Q27: Não iniciado | R27: Não iniciado | V27: 1° Visita - Henrique
A28: =IFERROR(__xludf.DUMMYFUNCTION("IFERROR(TO_TEXT(INDEX(Base!E:E, MATCH(B28, Base!A:A, 0))), ""mm.dd.yyyy"") "),"02.04.2026") -> 02.04.2026 | B28: 4175091770 | C28: {=IFERROR(INDEX(Base!I:I,MATCH(B28,Base!A:A,0)),"Nome do Cliente")} -> Guilerme de Souza Aranha Moreira | D28: {=IFERROR(INDEX(Base!G:G,MATCH(B28,Base!A:A,0)),"Modelo da Cond.")} -> AM100KXMDFH/TC | E28: {=IFERROR(INDEX(Base!H:H,MATCH(B28,Base!A:A,0)),"N° Serial")} -> 0FHMPAOX700006V | F28: =INT(TODAY() - DATE(RIGHT(A28,4), LEFT(A28,2), MID(A28,4,2))) -> 74 | G28: Sim, em estoque | H28: TRUE | I28: 46064 | J28: Não | K28: Não | L28: FALSE | N28: FALSE | O28: Sim | Q28: Realizado, não lançado | R28: Realizado, não lançado | V28: Reparo realizado pelo kaynã em 11/02/26
A29: =IFERROR(__xludf.DUMMYFUNCTION("IFERROR(TO_TEXT(INDEX(Base!E:E, MATCH(B29, Base!A:A, 0))), ""mm.dd.yyyy"") "),"02.05.2026") -> 02.05.2026 | B29: 4175100540 | C29: {=IFERROR(INDEX(Base!I:I,MATCH(B29,Base!A:A,0)),"Nome do Cliente")} -> FERNANDO A VASCONCELLOS | D29: {=IFERROR(INDEX(Base!G:G,MATCH(B29,Base!A:A,0)),"Modelo da Cond.")} -> AJ050AXJ2KH/AZ | E29: {=IFERROR(INDEX(Base!H:H,MATCH(B29,Base!A:A,0)),"N° Serial")} -> 02TGPXBRA00159M | F29: =INT(TODAY() - DATE(RIGHT(A29,4), LEFT(A29,2), MID(A29,4,2))) -> 73 | G29: Não | H29: TRUE | I29: 46086 | J29: Não | K29: Não | L29: FALSE | N29: TRUE | O29: Sim | P29: Sim | Q29: Realizado e lançado | R29: Realizado e lançado | V29: Henrique, aguardando email de aprovação
A30: =IFERROR(__xludf.DUMMYFUNCTION("IFERROR(TO_TEXT(INDEX(Base!E:E, MATCH(B30, Base!A:A, 0))), ""mm.dd.yyyy"") "),"02.09.2026") -> 02.09.2026 | B30: 4175126082 | C30: {=IFERROR(INDEX(Base!I:I,MATCH(B30,Base!A:A,0)),"Nome do Cliente")} -> JOEL ADRIANO DOS SANTOS | D30: {=IFERROR(INDEX(Base!G:G,MATCH(B30,Base!A:A,0)),"Modelo da Cond.")} -> AJ052TN1DKH/EA | E30: {=IFERROR(INDEX(Base!H:H,MATCH(B30,Base!A:A,0)),"N° Serial")} -> BLGDP3HX600112H | F30: =INT(TODAY() - DATE(RIGHT(A30,4), LEFT(A30,2), MID(A30,4,2))) -> 69 | G30: Sim, em estoque | H30: TRUE | I30: 46126 | J30: Não | K30: Não | L30: FALSE | N30: TRUE | O30: Sim | P30: Sim | Q30: Em execução | R30: Realizado, não lançado
A31: =IFERROR(__xludf.DUMMYFUNCTION("IFERROR(TO_TEXT(INDEX(Base!E:E, MATCH(B31, Base!A:A, 0))), ""mm.dd.yyyy"") "),"02.10.2026") -> 02.10.2026 | B31: 4175139235 | C31: {=IFERROR(INDEX(Base!I:I,MATCH(B31,Base!A:A,0)),"Nome do Cliente")} -> Vicente Balzano Neto | D31: {=IFERROR(INDEX(Base!G:G,MATCH(B31,Base!A:A,0)),"Modelo da Cond.")} -> AM220CXVAFH/AZ | E31: {=IFERROR(INDEX(Base!H:H,MATCH(B31,Base!A:A,0)),"N° Serial")} -> 0YP0PAOX900008Z | F31: =INT(TODAY() - DATE(RIGHT(A31,4), LEFT(A31,2), MID(A31,4,2))) -> 68 | G31: Não | H31: TRUE | I31: 46072 | J31: Não | K31: Não | L31: FALSE | N31: TRUE | O31: Sim | Q31: Realizado, não lançado | R31: Realizado, não lançado | U31: 1255231783 | V31: 1a. Visita César, problema de instalção
A32: =IFERROR(__xludf.DUMMYFUNCTION("IFERROR(TO_TEXT(INDEX(Base!E:E, MATCH(B32, Base!A:A, 0))), ""mm.dd.yyyy"") "),"02.11.2026") -> 02.11.2026 | B32: 4175145496 | C32: {=IFERROR(INDEX(Base!I:I,MATCH(B32,Base!A:A,0)),"Nome do Cliente")} -> ORPEC ENGENHARIA IND E COM LTDA | D32: {=IFERROR(INDEX(Base!G:G,MATCH(B32,Base!A:A,0)),"Modelo da Cond.")} -> AJ080AXJ4KH/AZ | E32: {=IFERROR(INDEX(Base!H:H,MATCH(B32,Base!A:A,0)),"N° Serial")} -> 02TMPXBXC00056P | F32: =INT(TODAY() - DATE(RIGHT(A32,4), LEFT(A32,2), MID(A32,4,2))) -> 67 | G32: Não | H32: TRUE | I32: 46087 | J32: Sim | K32: Sim, não solicitada | L32: TRUE | M32: 46108 | N32: FALSE | V32: Anderson - Solicitação de PÇ - Tem no estoque
A33: =IFERROR(__xludf.DUMMYFUNCTION("IFERROR(TO_TEXT(INDEX(Base!E:E, MATCH(B33, Base!A:A, 0))), ""mm.dd.yyyy"") "),"02.12.2026") -> 02.12.2026 | B33: 4175154735 | C33: {=IFERROR(INDEX(Base!I:I,MATCH(B33,Base!A:A,0)),"Nome do Cliente")} -> Jorge Pereira | D33: {=IFERROR(INDEX(Base!G:G,MATCH(B33,Base!A:A,0)),"Modelo da Cond.")} -> AJ050ANAPKH2AZ | E33: {=IFERROR(INDEX(Base!H:H,MATCH(B33,Base!A:A,0)),"N° Serial")} -> 0323PXCX500031P | F33: =INT(TODAY() - DATE(RIGHT(A33,4), LEFT(A33,2), MID(A33,4,2))) -> 66 | G33: Sim, em estoque | H33: TRUE | I33: 46125 | J33: Não | K33: Não | L33: FALSE | N33: TRUE | O33: Sim | P33: Sim | Q33: Em execução | R33: Não iniciado
A34: =IFERROR(__xludf.DUMMYFUNCTION("IFERROR(TO_TEXT(INDEX(Base!E:E, MATCH(B34, Base!A:A, 0))), ""mm.dd.yyyy"") "),"02.12.2026") -> 02.12.2026 | B34: 4175154947 | C34: {=IFERROR(INDEX(Base!I:I,MATCH(B34,Base!A:A,0)),"Nome do Cliente")} -> ALEXANDRE HENRIQUE JUNG | D34: {=IFERROR(INDEX(Base!G:G,MATCH(B34,Base!A:A,0)),"Modelo da Cond.")} -> AC018DN1DKG/AZ | E34: {=IFERROR(INDEX(Base!H:H,MATCH(B34,Base!A:A,0)),"N° Serial")} -> 0309PXAXA00381Y | F34: =INT(TODAY() - DATE(RIGHT(A34,4), LEFT(A34,2), MID(A34,4,2))) -> 66 | G34: Sim, em estoque | H34: TRUE | I34: 46085 | J34: Não | K34: Não | L34: FALSE | N34: TRUE | O34: Sim | Q34: Realizado e lançado | R34: Realizado e lançado | V34: Henrique, fechar OS sem SAW pois não tem nenhuma evidencia
A35: =IFERROR(__xludf.DUMMYFUNCTION("IFERROR(TO_TEXT(INDEX(Base!E:E, MATCH(B35, Base!A:A, 0))), ""mm.dd.yyyy"") "),"02.12.2026") -> 02.12.2026 | B35: 4175157549 | C35: {=IFERROR(INDEX(Base!I:I,MATCH(B35,Base!A:A,0)),"Nome do Cliente")} -> BRUNO LEONARDO FERREIRA | D35: {=IFERROR(INDEX(Base!G:G,MATCH(B35,Base!A:A,0)),"Modelo da Cond.")} -> AJ050AXJ2KH/AZ | E35: {=IFERROR(INDEX(Base!H:H,MATCH(B35,Base!A:A,0)),"N° Serial")} -> 02TGPXBX600298Y | F35: =INT(TODAY() - DATE(RIGHT(A35,4), LEFT(A35,2), MID(A35,4,2))) -> 66 | G35: Não | H35: FALSE | L35: FALSE | N35: FALSE
A36: =IFERROR(__xludf.DUMMYFUNCTION("IFERROR(TO_TEXT(INDEX(Base!E:E, MATCH(B36, Base!A:A, 0))), ""mm.dd.yyyy"") "),"02.13.2026") -> 02.13.2026 | B36: 4175163317 | C36: {=IFERROR(INDEX(Base!I:I,MATCH(B36,Base!A:A,0)),"Nome do Cliente")} -> AAC AR CONDICIONADO LTDA | D36: {=IFERROR(INDEX(Base!G:G,MATCH(B36,Base!A:A,0)),"Modelo da Cond.")} -> AJ025ANAPKH2AZ | E36: {=IFERROR(INDEX(Base!H:H,MATCH(B36,Base!A:A,0)),"N° Serial")} -> 0321PXCXA00875D | F36: =INT(TODAY() - DATE(RIGHT(A36,4), LEFT(A36,2), MID(A36,4,2))) -> 65 | G36: Sim, em estoque | H36: TRUE | I36: 46127 | J36: Não | K36: Não | L36: FALSE | N36: TRUE | O36: Sim | P36: Não | Q36: Em execução | R36: Realizado, não lançado
A37: =IFERROR(__xludf.DUMMYFUNCTION("IFERROR(TO_TEXT(INDEX(Base!E:E, MATCH(B37, Base!A:A, 0))), ""mm.dd.yyyy"") "),"02.19.2026") -> 02.19.2026 | B37: 4175199037 | C37: {=IFERROR(INDEX(Base!I:I,MATCH(B37,Base!A:A,0)),"Nome do Cliente")} -> NFT Treinamento e Saúde | D37: {=IFERROR(INDEX(Base!G:G,MATCH(B37,Base!A:A,0)),"Modelo da Cond.")} -> AM036TNVDKH/EU | E37: {=IFERROR(INDEX(Base!H:H,MATCH(B37,Base!A:A,0)),"N° Serial")} -> 0HG7PDCX800313A | F37: =INT(TODAY() - DATE(RIGHT(A37,4), LEFT(A37,2), MID(A37,4,2))) -> 59 | G37: Não | H37: TRUE | I37: 46083 | J37: Não | K37: Não | L37: FALSE | N37: TRUE | O37: Sim | Q37: Realizado, não lançado | R37: Realizado, não lançado | V37: Fausto
A38: =IFERROR(__xludf.DUMMYFUNCTION("IFERROR(TO_TEXT(INDEX(Base!E:E, MATCH(B38, Base!A:A, 0))), ""mm.dd.yyyy"") "),"02.19.2026") -> 02.19.2026 | B38: 4175199815 | C38: {=IFERROR(INDEX(Base!I:I,MATCH(B38,Base!A:A,0)),"Nome do Cliente")} -> Fabricio Passadore de Oliveir | D38: {=IFERROR(INDEX(Base!G:G,MATCH(B38,Base!A:A,0)),"Modelo da Cond.")} -> AJ068AXJ3KH/AZ | E38: {=IFERROR(INDEX(Base!H:H,MATCH(B38,Base!A:A,0)),"N° Serial")} -> 02TKPXBX800038K | F38: =INT(TODAY() - DATE(RIGHT(A38,4), LEFT(A38,2), MID(A38,4,2))) -> 59 | G38: Não | H38: TRUE | I38: 46097 | J38: Sim | K38: Sim, não solicitada | L38: FALSE | N38: FALSE | V38: Henrique - Visita Diagnóstica
A39: =IFERROR(__xludf.DUMMYFUNCTION("IFERROR(TO_TEXT(INDEX(Base!E:E, MATCH(B39, Base!A:A, 0))), ""mm.dd.yyyy"") "),"02.20.2026") -> 02.20.2026 | B39: 4175213137 | C39: {=IFERROR(INDEX(Base!I:I,MATCH(B39,Base!A:A,0)),"Nome do Cliente")} -> Wagner Oliveira | D39: {=IFERROR(INDEX(Base!G:G,MATCH(B39,Base!A:A,0)),"Modelo da Cond.")} -> AC048DXADKG/AZ | E39: {=IFERROR(INDEX(Base!H:H,MATCH(B39,Base!A:A,0)),"N° Serial")} -> 030YPXBY600011J | F39: =INT(TODAY() - DATE(RIGHT(A39,4), LEFT(A39,2), MID(A39,4,2))) -> 58 | G39: Não | H39: TRUE | I39: 46101 | J39: Sim | K39: Sim, solicitada | L39: FALSE | N39: FALSE
A40: =IFERROR(__xludf.DUMMYFUNCTION("IFERROR(TO_TEXT(INDEX(Base!E:E, MATCH(B40, Base!A:A, 0))), ""mm.dd.yyyy"") "),"02.20.2026") -> 02.20.2026 | B40: 4175209715 | C40: {=IFERROR(INDEX(Base!I:I,MATCH(B40,Base!A:A,0)),"Nome do Cliente")} -> Thales Cardoso | D40: {=IFERROR(INDEX(Base!G:G,MATCH(B40,Base!A:A,0)),"Modelo da Cond.")} -> AJ052DN1DKH2AZ | E40: {=IFERROR(INDEX(Base!H:H,MATCH(B40,Base!A:A,0)),"N° Serial")} -> M000 | F40: =INT(TODAY() - DATE(RIGHT(A40,4), LEFT(A40,2), MID(A40,4,2))) -> 58 | G40: Sim, em estoque | H40: FALSE | L40: FALSE | N40: FALSE
...

Sheet OSs Fechadas
A1: OS's Fechadas | B1: Nome do Cliente | C1: Data da Finalização OS | D1: Observações
A2: 4172884876 | B2: RICARDO ALBUQUERQUE ARTIOLI | C2: 45853
A3: 4172884906 | B3: ROSEMAR MIGUEL MALDANER | C3: 45854
A4: 4172884973 | B4: DIOGO GAZZI TICLY | C4: 45854
A5: 4172885001 | B5: Paulo Sergio Resende Peixo | C5: 45854
A6: 4173088304 | B6: Bruno Isidoro | C6: 45854 | D6: Cancelada
A7: 4173219431 | B7: RICARDO ALVES FERREIRA DA SI | C7: 45854
A8: 4173520611 | B8: DOUGLAS BONI FITARELLI | C8: 45854 | D8: Cancelada
A9: 4173272060 | B9: Angelo Miyake | C9: 45855
A10: 4172804738 | B10: JEISON GOMES FOLEGOTI | C10: 45855 | D10: Cancelado
A11: 4172805028 | B11: Fabio Hayashi | C11: 45856 | D11: Cancelado
A12: 4173136299 | B12: Bruno Isidoro | C12: 45856 | D12: Cancelado
A13: 4173359954 | B13: Aenon Empreendimentos Imob | C13: 45859
A14: 4173081395 | B14: UMBERTO ANTONIO NESPOLI | C14: 45860
A15: 4173083936 | B15: Sociedade Empresária Limitada | C15: 45861
A16: 4173391807 | B16: ANA MARIA APARECIDA LEON | C16: 45863 | D16: Cancelado
A17: 4173447607 | B17: Vinicius Scalco | C17: 45863
A18: 4173447671 | B18: Vinicius Scalco | C18: 45863
A19: 4173447675 | B19: Vinicius Scalco | C19: 45863
A20: 4173203785 | B20: Vinicius Scalco | C20: 45863
A21: 4172694782 | B21: CARLOS EDUARDO FERNANDES CA | C21: 45863
A22: 4173081395 | B22: Umberto Antônio Nespoli | C22: 45863
A23: 4172704937 | B23: JONI BERTOLLO | C23: 45866
A24: 4173444329 | B24: OLUCOES EM CONSTRUCOES LTDA CUSTODIO | C24: 45867
A25: 4172803743 | B25: MARIANE SILVA DE ARRUDA | C25: 45867 | D25: Cancelado
A26: 4172885055 | B26: RICARDO GONCALVES COSTA COUT | C26: 45867 | D26: Cancelado
A27: 4173305871 | B27: Fabio Hayashi | C27: 45875
A28: 4173345049 | B28: JULIANO CLOVIS MONTEIRO | C28: 45875 | D28: Cancelado
A29: 4173601604 | B29: JOSÉ INÁCIO TURATTI | C29: 45875
A30: 4173196402 | B30: FLAVIO HENRIQUE DA SILVA | C30: 45875 | D30: Cancelado
A31: 4173539614 | B31: Wellington Assis Santos | C31: 45875 | D31: Cancelado
A32: 4173263998 | B32: DANIELA GRESPI SOARES DE MEL | C32: 45875
A33: 4173311249 | B33: BRUNA TAYLA CABRAL DE VASC | C33: 45875
A34: 4173338330 | B34: Odilon Lisboa Medeiros | C34: 45875
A35: 4173535771 | B35: Janderson Almeida da Silva | C35: 45875
A36: 4173475586 | B36: Dumas Botter Rodrigues Borba | C36: 45876
A37: 4173122638 | B37: CARLOS ALVES DE OLIVEIRA | C37: 45876
A38: 4173384107 | B38: MARIANI DAN TAUFNER | C38: 45877
A39: 4173332030 | B39: Faria Lima Shopee REC | C39: 45881
A40: 4173332113 | B40: Faria Lima Shopee REC | C40: 45881
...

Sheet Solicitação de Peças
A1: 4174728314 | B1: OS | C1: Nome do Cliente | D1: Tipo do serviço | E1: Modelo da Condensadora / Evaporadora | F1: N° de série | G1: Peça a ser solicitada | H1: Peça Solicitada? | I1: Observações
A2: {=IFERROR(TEXT(INDEX(Base!E:E,MATCH(B2,Base!A:A,0)),"mm.dd.yyyy"),"mm.dd.yyyy")} -> mm.dd.yyyy | B2: 4174290904 | C2: {=IFERROR(INDEX(Base!I:I,MATCH(B2,Base!A:A,0)),"Nome do Cliente")} -> Nome do Cliente | D2: {=IFERROR(INDEX(Base!F:F,MATCH(B2,Base!A:A,0)),"Tipo do serv.")} -> Tipo do serv. | E2: {=IFERROR(INDEX(Base!G:G,MATCH(B2,Base!A:A,0)),"Modelo da Cond.")} -> Modelo da Cond. | F2: {=IFERROR(INDEX(Base!H:H,MATCH(B2,Base!A:A,0)),"N° Serial")} -> N° Serial | G2: Sensor | H2: Sim
A3: {=IFERROR(TEXT(INDEX(Base!E:E,MATCH(B3,Base!A:A,0)),"mm.dd.yyyy"),"mm.dd.yyyy")} -> 10.11.2025 | B3: 4174445115 | C3: {=IFERROR(INDEX(Base!I:I,MATCH(B3,Base!A:A,0)),"Nome do Cliente")} -> MARIO GOMES DA SILVA | D3: {=IFERROR(INDEX(Base!F:F,MATCH(B3,Base!A:A,0)),"Tipo do serv.")} -> Em Domicílio | E3: {=IFERROR(INDEX(Base!G:G,MATCH(B3,Base!A:A,0)),"Modelo da Cond.")} -> AC018DN1DKG/AZ | F3: {=IFERROR(INDEX(Base!H:H,MATCH(B3,Base!A:A,0)),"N° Serial")} -> 0309PXAY700069B | G3: Motor de Passo proxima visita chicote dos motores de passos | H3: Não
A4: {=IFERROR(TEXT(INDEX(Base!E:E,MATCH(B4,Base!A:A,0)),"mm.dd.yyyy"),"mm.dd.yyyy")} -> mm.dd.yyyy | B4: 4174600910 | C4: {=IFERROR(INDEX(Base!I:I,MATCH(B4,Base!A:A,0)),"Nome do Cliente")} -> Nome do Cliente | D4: {=IFERROR(INDEX(Base!F:F,MATCH(B4,Base!A:A,0)),"Tipo do serv.")} -> Tipo do serv. | E4: {=IFERROR(INDEX(Base!G:G,MATCH(B4,Base!A:A,0)),"Modelo da Cond.")} -> Modelo da Cond. | F4: {=IFERROR(INDEX(Base!H:H,MATCH(B4,Base!A:A,0)),"N° Serial")} -> N° Serial | G4: Sensor de nivel | H4: Sim
A5: {=IFERROR(TEXT(INDEX(Base!E:E,MATCH(B5,Base!A:A,0)),"mm.dd.yyyy"),"mm.dd.yyyy")} -> mm.dd.yyyy | B5: 4174477418 | C5: {=IFERROR(INDEX(Base!I:I,MATCH(B5,Base!A:A,0)),"Nome do Cliente")} -> Nome do Cliente | D5: {=IFERROR(INDEX(Base!F:F,MATCH(B5,Base!A:A,0)),"Tipo do serv.")} -> Tipo do serv. | E5: {=IFERROR(INDEX(Base!G:G,MATCH(B5,Base!A:A,0)),"Modelo da Cond.")} -> Modelo da Cond. | F5: {=IFERROR(INDEX(Base!H:H,MATCH(B5,Base!A:A,0)),"N° Serial")} -> N° Serial | G5: Compressor | H5: Sim
A6: {=IFERROR(TEXT(INDEX(Base!E:E,MATCH(B6,Base!A:A,0)),"mm.dd.yyyy"),"mm.dd.yyyy")} -> mm.dd.yyyy | B6: 4174482877 | C6: {=IFERROR(INDEX(Base!I:I,MATCH(B6,Base!A:A,0)),"Nome do Cliente")} -> Nome do Cliente | D6: {=IFERROR(INDEX(Base!F:F,MATCH(B6,Base!A:A,0)),"Tipo do serv.")} -> Tipo do serv. | E6: {=IFERROR(INDEX(Base!G:G,MATCH(B6,Base!A:A,0)),"Modelo da Cond.")} -> Modelo da Cond. | F6: {=IFERROR(INDEX(Base!H:H,MATCH(B6,Base!A:A,0)),"N° Serial")} -> N° Serial | G6: 4 compressores, acumuladores e filtro de oleo | H6: Não
A7: {=IFERROR(TEXT(INDEX(Base!E:E,MATCH(B7,Base!A:A,0)),"mm.dd.yyyy"),"mm.dd.yyyy")} -> mm.dd.yyyy | B7: 4174483387 | C7: {=IFERROR(INDEX(Base!I:I,MATCH(B7,Base!A:A,0)),"Nome do Cliente")} -> Nome do Cliente | D7: {=IFERROR(INDEX(Base!F:F,MATCH(B7,Base!A:A,0)),"Tipo do serv.")} -> Tipo do serv. | E7: {=IFERROR(INDEX(Base!G:G,MATCH(B7,Base!A:A,0)),"Modelo da Cond.")} -> Modelo da Cond. | F7: {=IFERROR(INDEX(Base!H:H,MATCH(B7,Base!A:A,0)),"N° Serial")} -> N° Serial | G7: Serpentina da evaporadora | H7: Sim | I7: Modelo: AJ025ANAPKH/AZ Serial: 02TDPXCXC00284A
A8: {=IFERROR(TEXT(INDEX(Base!E:E,MATCH(B8,Base!A:A,0)),"mm.dd.yyyy"),"mm.dd.yyyy")} -> mm.dd.yyyy | B8: 4174659575 | C8: {=IFERROR(INDEX(Base!I:I,MATCH(B8,Base!A:A,0)),"Nome do Cliente")} -> Nome do Cliente | D8: {=IFERROR(INDEX(Base!F:F,MATCH(B8,Base!A:A,0)),"Tipo do serv.")} -> Tipo do serv. | E8: {=IFERROR(INDEX(Base!G:G,MATCH(B8,Base!A:A,0)),"Modelo da Cond.")} -> Modelo da Cond. | F8: {=IFERROR(INDEX(Base!H:H,MATCH(B8,Base!A:A,0)),"N° Serial")} -> N° Serial | G8: Touch
A9: {=IFERROR(TEXT(INDEX(Base!E:E,MATCH(B9,Base!A:A,0)),"mm.dd.yyyy"),"mm.dd.yyyy")} -> 01.12.2025 | B9: 4174601418 | C9: {=IFERROR(INDEX(Base!I:I,MATCH(B9,Base!A:A,0)),"Nome do Cliente")} -> Bruno Henrique Dannas Pelogia | D9: {=IFERROR(INDEX(Base!F:F,MATCH(B9,Base!A:A,0)),"Tipo do serv.")} -> Em Domicílio | E9: {=IFERROR(INDEX(Base!G:G,MATCH(B9,Base!A:A,0)),"Modelo da Cond.")} -> AJ050AXJ2KH/AZ | F9: {=IFERROR(INDEX(Base!H:H,MATCH(B9,Base!A:A,0)),"N° Serial")} -> 02TGPXBX200299V | G9: Serpentina da condensadora, válvula de expansão e válvula 4 vias | H9: Não
A10: {=IFERROR(TEXT(INDEX(Base!E:E,MATCH(B10,Base!A:A,0)),"mm.dd.yyyy"),"mm.dd.yyyy")} -> mm.dd.yyyy | B10: 4174693613 | C10: {=IFERROR(INDEX(Base!I:I,MATCH(B10,Base!A:A,0)),"Nome do Cliente")} -> Nome do Cliente | D10: {=IFERROR(INDEX(Base!F:F,MATCH(B10,Base!A:A,0)),"Tipo do serv.")} -> Tipo do serv. | E10: {=IFERROR(INDEX(Base!G:G,MATCH(B10,Base!A:A,0)),"Modelo da Cond.")} -> Modelo da Cond. | F10: {=IFERROR(INDEX(Base!H:H,MATCH(B10,Base!A:A,0)),"N° Serial")} -> N° Serial | G10: Motor do ventilador da evaporadora
A11: {=IFERROR(TEXT(INDEX(Base!E:E,MATCH(B11,Base!A:A,0)),"mm.dd.yyyy"),"mm.dd.yyyy")} -> mm.dd.yyyy | B11: 4174735425 | C11: {=IFERROR(INDEX(Base!I:I,MATCH(B11,Base!A:A,0)),"Nome do Cliente")} -> Nome do Cliente | D11: {=IFERROR(INDEX(Base!F:F,MATCH(B11,Base!A:A,0)),"Tipo do serv.")} -> Tipo do serv. | E11: {=IFERROR(INDEX(Base!G:G,MATCH(B11,Base!A:A,0)),"Modelo da Cond.")} -> Modelo da Cond. | F11: {=IFERROR(INDEX(Base!H:H,MATCH(B11,Base!A:A,0)),"N° Serial")} -> N° Serial | G11: Bandeja de dreno | H11: Não
A12: {=IFERROR(TEXT(INDEX(Base!E:E,MATCH(B12,Base!A:A,0)),"mm.dd.yyyy"),"mm.dd.yyyy")} -> 10.11.2025 | B12: 4174445115 | C12: {=IFERROR(INDEX(Base!I:I,MATCH(B12,Base!A:A,0)),"Nome do Cliente")} -> MARIO GOMES DA SILVA | D12: {=IFERROR(INDEX(Base!F:F,MATCH(B12,Base!A:A,0)),"Tipo do serv.")} -> Em Domicílio | E12: {=IFERROR(INDEX(Base!G:G,MATCH(B12,Base!A:A,0)),"Modelo da Cond.")} -> AC018DN1DKG/AZ | F12: {=IFERROR(INDEX(Base!H:H,MATCH(B12,Base!A:A,0)),"N° Serial")} -> 0309PXAY700069B | G12: motor de passos placa moldura e aleta proxima visita levar . | H12: Não | I12: TAT 77
A13: {=IFERROR(TEXT(INDEX(Base!E:E,MATCH(B13,Base!A:A,0)),"mm.dd.yyyy"),"mm.dd.yyyy")} -> mm.dd.yyyy | B13: 4174477418 | C13: {=IFERROR(INDEX(Base!I:I,MATCH(B13,Base!A:A,0)),"Nome do Cliente")} -> Nome do Cliente | D13: {=IFERROR(INDEX(Base!F:F,MATCH(B13,Base!A:A,0)),"Tipo do serv.")} -> Tipo do serv. | E13: {=IFERROR(INDEX(Base!G:G,MATCH(B13,Base!A:A,0)),"Modelo da Cond.")} -> Modelo da Cond. | F13: {=IFERROR(INDEX(Base!H:H,MATCH(B13,Base!A:A,0)),"N° Serial")} -> N° Serial | G13: placa-mãe do condensador e do evaporador. | H13: Não | I13: TAT 73
A14: {=IFERROR(TEXT(INDEX(Base!E:E,MATCH(B14,Base!A:A,0)),"mm.dd.yyyy"),"mm.dd.yyyy")} -> mm.dd.yyyy | B14: 4174734499 | C14: {=IFERROR(INDEX(Base!I:I,MATCH(B14,Base!A:A,0)),"Nome do Cliente")} -> Nome do Cliente | D14: {=IFERROR(INDEX(Base!F:F,MATCH(B14,Base!A:A,0)),"Tipo do serv.")} -> Tipo do serv. | E14: {=IFERROR(INDEX(Base!G:G,MATCH(B14,Base!A:A,0)),"Modelo da Cond.")} -> Modelo da Cond. | F14: {=IFERROR(INDEX(Base!H:H,MATCH(B14,Base!A:A,0)),"N° Serial")} -> N° Serial | G14: Serpentina | H14: Não | I14: TAT 40
A15: {=IFERROR(TEXT(INDEX(Base!E:E,MATCH(B15,Base!A:A,0)),"mm.dd.yyyy"),"mm.dd.yyyy")} -> 12.19.2025 | B15: 4174748994 | C15: {=IFERROR(INDEX(Base!I:I,MATCH(B15,Base!A:A,0)),"Nome do Cliente")} -> Eliane Vignatti Avancini | D15: {=IFERROR(INDEX(Base!F:F,MATCH(B15,Base!A:A,0)),"Tipo do serv.")} -> Em Domicílio | E15: {=IFERROR(INDEX(Base!G:G,MATCH(B15,Base!A:A,0)),"Modelo da Cond.")} -> AC048TN4DKC/AZ | F15: {=IFERROR(INDEX(Base!H:H,MATCH(B15,Base!A:A,0)),"N° Serial")} -> BF09P3HW800039W | G15: placa eletrônica da evaporadora e da placa principal (display/controle) da condensadora | H15: Não | I15: TAT 38
A16: {=IFERROR(TEXT(INDEX(Base!E:E,MATCH(B16,Base!A:A,0)),"mm.dd.yyyy"),"mm.dd.yyyy")} -> 05.01.2026 | B16: 4174846790 | C16: {=IFERROR(INDEX(Base!I:I,MATCH(B16,Base!A:A,0)),"Nome do Cliente")} -> Fernando Romeu Miassi | D16: {=IFERROR(INDEX(Base!F:F,MATCH(B16,Base!A:A,0)),"Tipo do serv.")} -> Em Domicílio | E16: {=IFERROR(INDEX(Base!G:G,MATCH(B16,Base!A:A,0)),"Modelo da Cond.")} -> AM036TNVDKH/EU | F16: {=IFERROR(INDEX(Base!H:H,MATCH(B16,Base!A:A,0)),"N° Serial")} -> 0HG7PDAW900052X | G16: 3 serpentinas das unidades internas dos ambientes | H16: Não | I16: TAT 22
A17: {=IFERROR(TEXT(INDEX(Base!E:E,MATCH(B17,Base!A:A,0)),"mm.dd.yyyy"),"mm.dd.yyyy")} -> 01.16.2026 | B17: 4174946607 | C17: {=IFERROR(INDEX(Base!I:I,MATCH(B17,Base!A:A,0)),"Nome do Cliente")} -> COMERCIAL PROTON LIMITADA | D17: {=IFERROR(INDEX(Base!F:F,MATCH(B17,Base!A:A,0)),"Tipo do serv.")} -> Em Domicílio | E17: {=IFERROR(INDEX(Base!G:G,MATCH(B17,Base!A:A,0)),"Modelo da Cond.")} -> AM170TN4DKH/EA | F17: {=IFERROR(INDEX(Base!H:H,MATCH(B17,Base!A:A,0)),"N° Serial")} -> M000 | G17: Serpentina | H17: Não | I17: TAT 11
A18: {=IFERROR(TEXT(INDEX(Base!E:E,MATCH(B18,Base!A:A,0)),"mm.dd.yyyy"),"mm.dd.yyyy")} -> mm.dd.yyyy | B18: 4174947661 | C18: {=IFERROR(INDEX(Base!I:I,MATCH(B18,Base!A:A,0)),"Nome do Cliente")} -> Nome do Cliente | D18: {=IFERROR(INDEX(Base!F:F,MATCH(B18,Base!A:A,0)),"Tipo do serv.")} -> Tipo do serv. | E18: {=IFERROR(INDEX(Base!G:G,MATCH(B18,Base!A:A,0)),"Modelo da Cond.")} -> Modelo da Cond. | F18: {=IFERROR(INDEX(Base!H:H,MATCH(B18,Base!A:A,0)),"N° Serial")} -> N° Serial | G18: Compressor | H18: Não
A19: {=IFERROR(TEXT(INDEX(Base!E:E,MATCH(B19,Base!A:A,0)),"mm.dd.yyyy"),"mm.dd.yyyy")} -> mm.dd.yyyy | B19: 4174728314 | C19: {=IFERROR(INDEX(Base!I:I,MATCH(B19,Base!A:A,0)),"Nome do Cliente")} -> Nome do Cliente | D19: {=IFERROR(INDEX(Base!F:F,MATCH(B19,Base!A:A,0)),"Tipo do serv.")} -> Tipo do serv. | E19: {=IFERROR(INDEX(Base!G:G,MATCH(B19,Base!A:A,0)),"Modelo da Cond.")} -> Modelo da Cond. | F19: {=IFERROR(INDEX(Base!H:H,MATCH(B19,Base!A:A,0)),"N° Serial")} -> N° Serial | G19: Compressor | H19: Não
A20: {=IFERROR(TEXT(INDEX(Base!E:E,MATCH(B20,Base!A:A,0)),"mm.dd.yyyy"),"mm.dd.yyyy")} -> 01.19.2026 | B20: 4174960583 | C20: {=IFERROR(INDEX(Base!I:I,MATCH(B20,Base!A:A,0)),"Nome do Cliente")} -> William Robert Nahra Filho | D20: {=IFERROR(INDEX(Base!F:F,MATCH(B20,Base!A:A,0)),"Tipo do serv.")} -> Em Domicílio | E20: {=IFERROR(INDEX(Base!G:G,MATCH(B20,Base!A:A,0)),"Modelo da Cond.")} -> AC024DN4DKG/AZ | F20: {=IFERROR(INDEX(Base!H:H,MATCH(B20,Base!A:A,0)),"N° Serial")} -> 030FPXAX200036P | G20: Cliente informa o erro E153, referente a bomba de drenagem. Sugerimos a ASC levar a placa da evaporadora e o kit sensor+sensor de nível. | H20: Não
A21: {=IFERROR(TEXT(INDEX(Base!E:E,MATCH(B21,Base!A:A,0)),"mm.dd.yyyy"),"mm.dd.yyyy")} -> mm.dd.yyyy | B21: 4174973973 | C21: {=IFERROR(INDEX(Base!I:I,MATCH(B21,Base!A:A,0)),"Nome do Cliente")} -> Nome do Cliente | D21: {=IFERROR(INDEX(Base!F:F,MATCH(B21,Base!A:A,0)),"Tipo do serv.")} -> Tipo do serv. | E21: {=IFERROR(INDEX(Base!G:G,MATCH(B21,Base!A:A,0)),"Modelo da Cond.")} -> Modelo da Cond. | F21: {=IFERROR(INDEX(Base!H:H,MATCH(B21,Base!A:A,0)),"N° Serial")} -> N° Serial | G21: Cliente informa que não consegue realizar a configuração do módulo wi fi. Sugerimos a ASC levar o módulo wi fi e a placa da evaporadora. | H21: Não
A22: {=IFERROR(TEXT(INDEX(Base!E:E,MATCH(B22,Base!A:A,0)),"mm.dd.yyyy"),"mm.dd.yyyy")} -> mm.dd.yyyy | B22: 4174984195 | C22: {=IFERROR(INDEX(Base!I:I,MATCH(B22,Base!A:A,0)),"Nome do Cliente")} -> Nome do Cliente | D22: {=IFERROR(INDEX(Base!F:F,MATCH(B22,Base!A:A,0)),"Tipo do serv.")} -> Tipo do serv. | E22: {=IFERROR(INDEX(Base!G:G,MATCH(B22,Base!A:A,0)),"Modelo da Cond.")} -> Modelo da Cond. | F22: {=IFERROR(INDEX(Base!H:H,MATCH(B22,Base!A:A,0)),"N° Serial")} -> N° Serial | G22: Sugerimos a ASC levar não apenas a placa, mas também o kit bomba+sensor de nível. | H22: Não
A23: {=IFERROR(TEXT(INDEX(Base!E:E,MATCH(B23,Base!A:A,0)),"mm.dd.yyyy"),"mm.dd.yyyy")} -> mm.dd.yyyy | B23: 4174984272 | C23: {=IFERROR(INDEX(Base!I:I,MATCH(B23,Base!A:A,0)),"Nome do Cliente")} -> Nome do Cliente | D23: {=IFERROR(INDEX(Base!F:F,MATCH(B23,Base!A:A,0)),"Tipo do serv.")} -> Tipo do serv. | E23: {=IFERROR(INDEX(Base!G:G,MATCH(B23,Base!A:A,0)),"Modelo da Cond.")} -> Modelo da Cond. | F23: {=IFERROR(INDEX(Base!H:H,MATCH(B23,Base!A:A,0)),"N° Serial")} -> N° Serial | G23: Cliente informa o erro E153, referente a bomba de drenagem. Sugerimos a ASC levar a placa e o kit bomba+sensor de nível. | H23: Não
A24: {=IFERROR(TEXT(INDEX(Base!E:E,MATCH(B24,Base!A:A,0)),"mm.dd.yyyy"),"mm.dd.yyyy")} -> mm.dd.yyyy | B24: 4174772084 | C24: {=IFERROR(INDEX(Base!I:I,MATCH(B24,Base!A:A,0)),"Nome do Cliente")} -> Nome do Cliente | D24: {=IFERROR(INDEX(Base!F:F,MATCH(B24,Base!A:A,0)),"Tipo do serv.")} -> Tipo do serv. | E24: {=IFERROR(INDEX(Base!G:G,MATCH(B24,Base!A:A,0)),"Modelo da Cond.")} -> Modelo da Cond. | F24: {=IFERROR(INDEX(Base!H:H,MATCH(B24,Base!A:A,0)),"N° Serial")} -> N° Serial | G24: placas do kit wi-fi | H24: Não
A25: {=IFERROR(TEXT(INDEX(Base!E:E,MATCH(B25,Base!A:A,0)),"mm.dd.yyyy"),"mm.dd.yyyy")} -> mm.dd.yyyy | B25: 4174772259 | C25: {=IFERROR(INDEX(Base!I:I,MATCH(B25,Base!A:A,0)),"Nome do Cliente")} -> Nome do Cliente | D25: {=IFERROR(INDEX(Base!F:F,MATCH(B25,Base!A:A,0)),"Tipo do serv.")} -> Tipo do serv. | E25: {=IFERROR(INDEX(Base!G:G,MATCH(B25,Base!A:A,0)),"Modelo da Cond.")} -> Modelo da Cond. | F25: {=IFERROR(INDEX(Base!H:H,MATCH(B25,Base!A:A,0)),"N° Serial")} -> N° Serial | G25: válvula EEV da evaporadora | H25: Não
A26: {=IFERROR(TEXT(INDEX(Base!E:E,MATCH(B26,Base!A:A,0)),"mm.dd.yyyy"),"mm.dd.yyyy")} -> 07.01.2026 | B26: 4174866947 | C26: {=IFERROR(INDEX(Base!I:I,MATCH(B26,Base!A:A,0)),"Nome do Cliente")} -> Sidnei Dos Reis Lopes | D26: {=IFERROR(INDEX(Base!F:F,MATCH(B26,Base!A:A,0)),"Tipo do serv.")} -> Em Domicílio | E26: {=IFERROR(INDEX(Base!G:G,MATCH(B26,Base!A:A,0)),"Modelo da Cond.")} -> AC018DN1DKG/AZ | F26: {=IFERROR(INDEX(Base!H:H,MATCH(B26,Base!A:A,0)),"N° Serial")} -> 0309PXAY400025P | G26: placa da evaporadora | H26: Não
A27: {=IFERROR(TEXT(INDEX(Base!E:E,MATCH(B27,Base!A:A,0)),"mm.dd.yyyy"),"mm.dd.yyyy")} -> mm.dd.yyyy | B27: 4174731148 | C27: {=IFERROR(INDEX(Base!I:I,MATCH(B27,Base!A:A,0)),"Nome do Cliente")} -> Nome do Cliente | D27: {=IFERROR(INDEX(Base!F:F,MATCH(B27,Base!A:A,0)),"Tipo do serv.")} -> Tipo do serv. | E27: {=IFERROR(INDEX(Base!G:G,MATCH(B27,Base!A:A,0)),"Modelo da Cond.")} -> Modelo da Cond. | F27: {=IFERROR(INDEX(Base!H:H,MATCH(B27,Base!A:A,0)),"N° Serial")} -> N° Serial | G27: VALVE GEAR EXPAN | H27: Não
A28: {=IFERROR(TEXT(INDEX(Base!E:E,MATCH(B28,Base!A:A,0)),"mm.dd.yyyy"),"mm.dd.yyyy")} -> 01.14.2026 | B28: 4174925699 | C28: {=IFERROR(INDEX(Base!I:I,MATCH(B28,Base!A:A,0)),"Nome do Cliente")} -> Richard Frank | D28: {=IFERROR(INDEX(Base!F:F,MATCH(B28,Base!A:A,0)),"Tipo do serv.")} -> Em Domicílio | E28: {=IFERROR(INDEX(Base!G:G,MATCH(B28,Base!A:A,0)),"Modelo da Cond.")} -> AJ025ANAPKH2AZ | F28: {=IFERROR(INDEX(Base!H:H,MATCH(B28,Base!A:A,0)),"N° Serial")} -> 0321PXCXA01720X | G28: serpentina da evaporadora | H28: Não
A29: {=IFERROR(TEXT(INDEX(Base!E:E,MATCH(B29,Base!A:A,0)),"mm.dd.yyyy"),"mm.dd.yyyy")} -> mm.dd.yyyy | B29: 4174554429 | C29: {=IFERROR(INDEX(Base!I:I,MATCH(B29,Base!A:A,0)),"Nome do Cliente")} -> Nome do Cliente | D29: {=IFERROR(INDEX(Base!F:F,MATCH(B29,Base!A:A,0)),"Tipo do serv.")} -> Tipo do serv. | E29: {=IFERROR(INDEX(Base!G:G,MATCH(B29,Base!A:A,0)),"Modelo da Cond.")} -> Modelo da Cond. | F29: {=IFERROR(INDEX(Base!H:H,MATCH(B29,Base!A:A,0)),"N° Serial")} -> N° Serial | G29: ASSY PCB MAIN-IN;SW,INDOOR,AC5000B,260*7 | H29: Não
... A39: {=IFERROR(TEXT(INDEX(Base!E:E,MATCH(B39,Base!A:A,0)),"mm.dd.yyyy"),"mm.dd.yyyy")} -> 01.23.2026 | B39: 4175001531 | C39: {=IFERROR(INDEX(Base!I:I,MATCH(B39,Base!A:A,0)),"Nome do Cliente")} -> Marcos Phaulo Passos Bastos | D39: {=IFERROR(INDEX(Base!F:F,MATCH(B39,Base!A:A,0)),"Tipo do serv.")} -> Em Domicílio | E39: {=IFERROR(INDEX(Base!G:G,MATCH(B39,Base!A:A,0)),"Modelo da Cond.")} -> AJ080AXJ4KH/AZ | F39: {=IFERROR(INDEX(Base!H:H,MATCH(B39,Base!A:A,0)),"N° Serial")} -> 02TMPXBY100174H | G39: placas main e sub | H39: Não
A40: {=IFERROR(TEXT(INDEX(Base!E:E,MATCH(B40,Base!A:A,0)),"mm.dd.yyyy"),"mm.dd.yyyy")} -> mm.dd.yyyy | B40: 4174693613 | C40: {=IFERROR(INDEX(Base!I:I,MATCH(B40,Base!A:A,0)),"Nome do Cliente")} -> Nome do Cliente | D40: {=IFERROR(INDEX(Base!F:F,MATCH(B40,Base!A:A,0)),"Tipo do serv.")} -> Tipo do serv. | E40: {=IFERROR(INDEX(Base!G:G,MATCH(B40,Base!A:A,0)),"Modelo da Cond.")} -> Modelo da Cond. | F40: {=IFERROR(INDEX(Base!H:H,MATCH(B40,Base!A:A,0)),"N° Serial")} -> N° Serial | G40: 2 motores e 2 placa da evap | H40: Não | I40: Fausto
A41: {=IFERROR(TEXT(INDEX(Base!E:E,MATCH(B41,Base!A:A,0)),"mm.dd.yyyy"),"mm.dd.yyyy")} -> mm.dd.yyyy | B41: 4174728314 | C41: {=IFERROR(INDEX(Base!I:I,MATCH(B41,Base!A:A,0)),"Nome do Cliente")} -> Nome do Cliente | D41: {=IFERROR(INDEX(Base!F:F,MATCH(B41,Base!A:A,0)),"Tipo do serv.")} -> Tipo do serv. | E41: {=IFERROR(INDEX(Base!G:G,MATCH(B41,Base!A:A,0)),"Modelo da Cond.")} -> Modelo da Cond. | F41: {=IFERROR(INDEX(Base!H:H,MATCH(B41,Base!A:A,0)),"N° Serial")} -> N° Serial | G41: Faz-se necessária compra de peça (Compressor) | H41: Não
A42: {=IFERROR(TEXT(INDEX(Base!E:E,MATCH(B42,Base!A:A,0)),"mm.dd.yyyy"),"mm.dd.yyyy")} -> mm.dd.yyyy | B42: 4175136315 | C42: {=IFERROR(INDEX(Base!I:I,MATCH(B42,Base!A:A,0)),"Nome do Cliente")} -> Nome do Cliente | D42: {=IFERROR(INDEX(Base!F:F,MATCH(B42,Base!A:A,0)),"Tipo do serv.")} -> Tipo do serv. | E42: {=IFERROR(INDEX(Base!G:G,MATCH(B42,Base!A:A,0)),"Modelo da Cond.")} -> Modelo da Cond. | F42: {=IFERROR(INDEX(Base!H:H,MATCH(B42,Base!A:A,0)),"N° Serial")} -> N° Serial | G42: Compressor DS-GB066FAVB ou similar. | H42: Não
A43: {=IFERROR(TEXT(INDEX(Base!E:E,MATCH(B43,Base!A:A,0)),"mm.dd.yyyy"),"mm.dd.yyyy")} -> 01.27.2026 | B43: 4175021965 | C43: {=IFERROR(INDEX(Base!I:I,MATCH(B43,Base!A:A,0)),"Nome do Cliente")} -> MARCOS FERREIRA | D43: {=IFERROR(INDEX(Base!F:F,MATCH(B43,Base!A:A,0)),"Tipo do serv.")} -> Em Domicílio | E43: {=IFERROR(INDEX(Base!G:G,MATCH(B43,Base!A:A,0)),"Modelo da Cond.")} -> AJ050AXJ2KH/AZ | F43: {=IFERROR(INDEX(Base!H:H,MATCH(B43,Base!A:A,0)),"N° Serial")} -> 02TGPXBY700025R | G43: serpentina da evaporadora | H43: Não
A44: {=IFERROR(TEXT(INDEX(Base!E:E,MATCH(B44,Base!A:A,0)),"mm.dd.yyyy"),"mm.dd.yyyy")} -> 02.02.2026 | B44: 4175068842 | C44: {=IFERROR(INDEX(Base!I:I,MATCH(B44,Base!A:A,0)),"Nome do Cliente")} -> GABRIELA LUCIANO BORRI ARANDA | D44: {=IFERROR(INDEX(Base!F:F,MATCH(B44,Base!A:A,0)),"Tipo do serv.")} -> Em Domicílio | E44: {=IFERROR(INDEX(Base!G:G,MATCH(B44,Base!A:A,0)),"Modelo da Cond.")} -> AJ100AXJ5KH/AZ | F44: {=IFERROR(INDEX(Base!H:H,MATCH(B44,Base!A:A,0)),"N° Serial")} -> BLK6P3CX400095V | G44: Placa inverter da condensadora, | H44: Não | I44: DB92-04560A (PLACA E TROCADOR) ideal DB92-04535A (APENAS PLACA) caso não encontre pelo cod acima
A45: {=IFERROR(TEXT(INDEX(Base!E:E,MATCH(B45,Base!A:A,0)),"mm.dd.yyyy"),"mm.dd.yyyy")} -> 04.02.2026 | B45: 4175085235 | C45: {=IFERROR(INDEX(Base!I:I,MATCH(B45,Base!A:A,0)),"Nome do Cliente")} -> Vinicius Milhan Hipolito | D45: {=IFERROR(INDEX(Base!F:F,MATCH(B45,Base!A:A,0)),"Tipo do serv.")} -> Em Domicílio | E45: {=IFERROR(INDEX(Base!G:G,MATCH(B45,Base!A:A,0)),"Modelo da Cond.")} -> AC024DN4DKG/AZ | F45: {=IFERROR(INDEX(Base!H:H,MATCH(B45,Base!A:A,0)),"N° Serial")} -> 030FPXAXA00141N | G45: Bomba de dreno, Kit Wifi (DB90-11882L) e placa principal de cassete 4 vias | H45: Não
A46: {=IFERROR(TEXT(INDEX(Base!E:E,MATCH(B46,Base!A:A,0)),"mm.dd.yyyy"),"mm.dd.yyyy")} -> 01.14.2026 | B46: 4174925640 | C46: {=IFERROR(INDEX(Base!I:I,MATCH(B46,Base!A:A,0)),"Nome do Cliente")} -> Thiago Nascimento Pontes | D46: {=IFERROR(INDEX(Base!F:F,MATCH(B46,Base!A:A,0)),"Tipo do serv.")} -> Em Domicílio | E46: {=IFERROR(INDEX(Base!G:G,MATCH(B46,Base!A:A,0)),"Modelo da Cond.")} -> AJ100DXJ5KH/AZ | F46: {=IFERROR(INDEX(Base!H:H,MATCH(B46,Base!A:A,0)),"N° Serial")} -> 0344PXBY500159H | G46: Kit Wifi | H46: Não
A47: {=IFERROR(TEXT(INDEX(Base!E:E,MATCH(B47,Base!A:A,0)),"mm.dd.yyyy"),"mm.dd.yyyy")} -> 11.02.2026 | B47: 4175145496 | C47: {=IFERROR(INDEX(Base!I:I,MATCH(B47,Base!A:A,0)),"Nome do Cliente")} -> ORPEC ENGENHARIA IND E COM LTDA | D47: {=IFERROR(INDEX(Base!F:F,MATCH(B47,Base!A:A,0)),"Tipo do serv.")} -> Em Domicílio | E47: {=IFERROR(INDEX(Base!G:G,MATCH(B47,Base!A:A,0)),"Modelo da Cond.")} -> AJ080AXJ4KH/AZ | F47: {=IFERROR(INDEX(Base!H:H,MATCH(B47,Base!A:A,0)),"N° Serial")} -> 02TMPXBXC00056P | G47: Placa principal da condensadora | H47: Não
A48: {=IFERROR(TEXT(INDEX(Base!E:E,MATCH(B48,Base!A:A,0)),"mm.dd.yyyy"),"mm.dd.yyyy")} -> 01.30.2026 | B48: 4175055490 | C48: {=IFERROR(INDEX(Base!I:I,MATCH(B48,Base!A:A,0)),"Nome do Cliente")} -> GIULIA MADEIROS GUIDONI | D48: {=IFERROR(INDEX(Base!F:F,MATCH(B48,Base!A:A,0)),"Tipo do serv.")} -> Em Domicílio | E48: {=IFERROR(INDEX(Base!G:G,MATCH(B48,Base!A:A,0)),"Modelo da Cond.")} -> AJ100DXJ5KH/AZ | F48: {=IFERROR(INDEX(Base!H:H,MATCH(B48,Base!A:A,0)),"N° Serial")} -> 0344PXBY900196P | G48: Placa Inverter e Main condensadora | H48: Não
A49: {=IFERROR(TEXT(INDEX(Base!E:E,MATCH(B49,Base!A:A,0)),"mm.dd.yyyy"),"mm.dd.yyyy")} -> 02.19.2026 | B49: 4175199815 | C49: {=IFERROR(INDEX(Base!I:I,MATCH(B49,Base!A:A,0)),"Nome do Cliente")} -> Fabricio Passadore de Oliveir | D49: {=IFERROR(INDEX(Base!F:F,MATCH(B49,Base!A:A,0)),"Tipo do serv.")} -> Em Domicílio | E49: {=IFERROR(INDEX(Base!G:G,MATCH(B49,Base!A:A,0)),"Modelo da Cond.")} -> AJ068AXJ3KH/AZ | F49: {=IFERROR(INDEX(Base!H:H,MATCH(B49,Base!A:A,0)),"N° Serial")} -> 02TKPXBX800038K | G49: Serpentina da evaporadora (DB96-24830F) mod. :AJ025ANAPKH2AZ n/s : 0321PXCX500959Y | H49: Não
...

Sheet Banco de Informações OSs Cancel
A1: Data de Abertura | B1: OS | C1: Nome do Cliente | D1: Tipo do serviço | E1: Modelo da Condensadora / Evaporadora | F1: N° de série | G1: Agendado? | H1: Data da Visita | I1: Peça Nescessária? | J1: Peça Solicitada? | K1: Peça em Estoque? | L1: Necessita Retorno? | M1: Retorno Agendado? | N1: Data da 2° Visita | O1: Peça Nescessária para Retorno? | P1: Peça Solicitada para Retorno? | Q1: Peça em Estoque para Retorno? | R1: Toda Documentação está disponível? | S1: SAW ( Extra Man ) | T1: SAW ( KM ) | U1: N° GA (SÓ PARA AM) | V1: Data da Finalização OS | W1: Analista | X1: Observações
A2: {=IFERROR(TEXT(INDEX(Base!E:E,MATCH(B2,Base!A:A,0)),"mm.dd.yyyy"),"mm.dd.yyyy")} -> mm.dd.yyyy | C2: {=IFERROR(INDEX(Base!I:I,MATCH(B2,Base!A:A,0)),"Nome do Cliente")} -> Nome do Cliente | D2: {=IFERROR(INDEX(Base!F:F,MATCH(B2,Base!A:A,0)),"Tipo do serv.")} -> Tipo do serv. | E2: {=IFERROR(INDEX(Base!G:G,MATCH(B2,Base!A:A,0)),"Modelo da Cond.")} -> Modelo da Cond. | F2: {=IFERROR(INDEX(Base!H:H,MATCH(B2,Base!A:A,0)),"N° Serial")} -> N° Serial | G2: FALSE | I2: Não | J2: Não | K2: Não | L2: Não | M2: FALSE | O2: Não | P2: Não | Q2: Não | R2: Não | S2: Não iniciado | T2: Não iniciado
A3: {=IFERROR(TEXT(INDEX(Base!E:E,MATCH(B3,Base!A:A,0)),"mm.dd.yyyy"),"mm.dd.yyyy")} -> mm.dd.yyyy | C3: {=IFERROR(INDEX(Base!I:I,MATCH(B3,Base!A:A,0)),"Nome do Cliente")} -> Nome do Cliente | D3: {=IFERROR(INDEX(Base!F:F,MATCH(B3,Base!A:A,0)),"Tipo do serv.")} -> Tipo do serv. | E3: {=IFERROR(INDEX(Base!G:G,MATCH(B3,Base!A:A,0)),"Modelo da Cond.")} -> Modelo da Cond. | F3: {=IFERROR(INDEX(Base!H:H,MATCH(B3,Base!A:A,0)),"N° Serial")} -> N° Serial | G3: FALSE | I3: Não | J3: Não | K3: Não | L3: Não | M3: FALSE | O3: Não | P3: Não | Q3: Não | R3: Não | S3: Não iniciado | T3: Não iniciado
A4: {=IFERROR(TEXT(INDEX(Base!E:E,MATCH(B4,Base!A:A,0)),"mm.dd.yyyy"),"mm.dd.yyyy")} -> mm.dd.yyyy | C4: {=IFERROR(INDEX(Base!I:I,MATCH(B4,Base!A:A,0)),"Nome do Cliente")} -> Nome do Cliente | D4: {=IFERROR(INDEX(Base!F:F,MATCH(B4,Base!A:A,0)),"Tipo do serv.")} -> Tipo do serv. | E4: {=IFERROR(INDEX(Base!G:G,MATCH(B4,Base!A:A,0)),"Modelo da Cond.")} -> Modelo da Cond. | F4: {=IFERROR(INDEX(Base!H:H,MATCH(B4,Base!A:A,0)),"N° Serial")} -> N° Serial | G4: FALSE | I4: Não | J4: Não | K4: Não | L4: Não | M4: FALSE | O4: Não | P4: Não | Q4: Não | R4: Não | S4: Não iniciado | T4: Não iniciado
A5: {=IFERROR(TEXT(INDEX(Base!E:E,MATCH(B5,Base!A:A,0)),"mm.dd.yyyy"),"mm.dd.yyyy")} -> mm.dd.yyyy | C5: {=IFERROR(INDEX(Base!I:I,MATCH(B5,Base!A:A,0)),"Nome do Cliente")} -> Nome do Cliente | D5: {=IFERROR(INDEX(Base!F:F,MATCH(B5,Base!A:A,0)),"Tipo do serv.")} -> Tipo do serv. | E5: {=IFERROR(INDEX(Base!G:G,MATCH(B5,Base!A:A,0)),"Modelo da Cond.")} -> Modelo da Cond. | F5: {=IFERROR(INDEX(Base!H:H,MATCH(B5,Base!A:A,0)),"N° Serial")} -> N° Serial | G5: FALSE | I5: Não | J5: Não | K5: Não | L5: Não | M5: FALSE | O5: Não | P5: Não | Q5: Não | R5: Não | S5: Não iniciado | T5: Não iniciado
A6: {=IFERROR(TEXT(INDEX(Base!E:E,MATCH(B6,Base!A:A,0)),"mm.dd.yyyy"),"mm.dd.yyyy")} -> mm.dd.yyyy | C6: {=IFERROR(INDEX(Base!I:I,MATCH(B6,Base!A:A,0)),"Nome do Cliente")} -> Nome do Cliente | D6: {=IFERROR(INDEX(Base!F:F,MATCH(B6,Base!A:A,0)),"Tipo do serv.")} -> Tipo do serv. | E6: {=IFERROR(INDEX(Base!G:G,MATCH(B6,Base!A:A,0)),"Modelo da Cond.")} -> Modelo da Cond. | F6: {=IFERROR(INDEX(Base!H:H,MATCH(B6,Base!A:A,0)),"N° Serial")} -> N° Serial | G6: FALSE | I6: Não | J6: Não | K6: Não | L6: Não | M6: FALSE | O6: Não | P6: Não | Q6: Não | R6: Não | S6: Não iniciado | T6: Não iniciado
A7: {=IFERROR(TEXT(INDEX(Base!E:E,MATCH(B7,Base!A:A,0)),"mm.dd.yyyy"),"mm.dd.yyyy")} -> mm.dd.yyyy | C7: {=IFERROR(INDEX(Base!I:I,MATCH(B7,Base!A:A,0)),"Nome do Cliente")} -> Nome do Cliente | D7: {=IFERROR(INDEX(Base!F:F,MATCH(B7,Base!A:A,0)),"Tipo do serv.")} -> Tipo do serv. | E7: {=IFERROR(INDEX(Base!G:G,MATCH(B7,Base!A:A,0)),"Modelo da Cond.")} -> Modelo da Cond. | F7: {=IFERROR(INDEX(Base!H:H,MATCH(B7,Base!A:A,0)),"N° Serial")} -> N° Serial | G7: FALSE | I7: Não | J7: Não | K7: Não | L7: Não | M7: FALSE | O7: Não | P7: Não | Q7: Não | R7: Não | S7: Não iniciado | T7: Não iniciado
A8: {=IFERROR(TEXT(INDEX(Base!E:E,MATCH(B8,Base!A:A,0)),"mm.dd.yyyy"),"mm.dd.yyyy")} -> mm.dd.yyyy | C8: {=IFERROR(INDEX(Base!I:I,MATCH(B8,Base!A:A,0)),"Nome do Cliente")} -> Nome do Cliente | D8: {=IFERROR(INDEX(Base!F:F,MATCH(B8,Base!A:A,0)),"Tipo do serv.")} -> Tipo do serv. | E8: {=IFERROR(INDEX(Base!G:G,MATCH(B8,Base!A:A,0)),"Modelo da Cond.")} -> Modelo da Cond. | F8: {=IFERROR(INDEX(Base!H:H,MATCH(B8,Base!A:A,0)),"N° Serial")} -> N° Serial | G8: FALSE | I8: Não | J8: Não | K8: Não | L8: Não | M8: FALSE | O8: Não | P8: Não | Q8: Não | R8: Não | S8: Não iniciado | T8: Não iniciado
A9: {=IFERROR(TEXT(INDEX(Base!E:E,MATCH(B9,Base!A:A,0)),"mm.dd.yyyy"),"mm.dd.yyyy")} -> mm.dd.yyyy | C9: {=IFERROR(INDEX(Base!I:I,MATCH(B9,Base!A:A,0)),"Nome do Cliente")} -> Nome do Cliente | D9: {=IFERROR(INDEX(Base!F:F,MATCH(B9,Base!A:A,0)),"Tipo do serv.")} -> Tipo do serv. | E9: {=IFERROR(INDEX(Base!G:G,MATCH(B9,Base!A:A,0)),"Modelo da Cond.")} -> Modelo da Cond. | F9: {=IFERROR(INDEX(Base!H:H,MATCH(B9,Base!A:A,0)),"N° Serial")} -> N° Serial | G9: FALSE | I9: Não | J9: Não | K9: Não | L9: Não | M9: FALSE | O9: Não | P9: Não | Q9: Não | R9: Não | S9: Não iniciado | T9: Não iniciado
A10: {=IFERROR(TEXT(INDEX(Base!E:E,MATCH(B10,Base!A:A,0)),"mm.dd.yyyy"),"mm.dd.yyyy")} -> mm.dd.yyyy | C10: {=IFERROR(INDEX(Base!I:I,MATCH(B10,Base!A:A,0)),"Nome do Cliente")} -> Nome do Cliente | D10: {=IFERROR(INDEX(Base!F:F,MATCH(B10,Base!A:A,0)),"Tipo do serv.")} -> Tipo do serv. | E10: {=IFERROR(INDEX(Base!G:G,MATCH(B10,Base!A:A,0)),"Modelo da Cond.")} -> Modelo da Cond. | F10: {=IFERROR(INDEX(Base!H:H,MATCH(B10,Base!A:A,0)),"N° Serial")} -> N° Serial | G10: FALSE | I10: Não | J10: Não | K10: Não | L10: Não | M10: FALSE | O10: Não | P10: Não | Q10: Não | R10: Não | S10: Não iniciado | T10: Não iniciado
A11: {=IFERROR(TEXT(INDEX(Base!E:E,MATCH(B11,Base!A:A,0)),"mm.dd.yyyy"),"mm.dd.yyyy")} -> mm.dd.yyyy | C11: {=IFERROR(INDEX(Base!I:I,MATCH(B11,Base!A:A,0)),"Nome do Cliente")} -> Nome do Cliente | D11: {=IFERROR(INDEX(Base!F:F,MATCH(B11,Base!A:A,0)),"Tipo do serv.")} -> Tipo do serv. | E11: {=IFERROR(INDEX(Base!G:G,MATCH(B11,Base!A:A,0)),"Modelo da Cond.")} -> Modelo da Cond. | F11: {=IFERROR(INDEX(Base!H:H,MATCH(B11,Base!A:A,0)),"N° Serial")} -> N° Serial | G11: FALSE | I11: Não | J11: Não | K11: Não | L11: Não | M11: FALSE | O11: Não | P11: Não | Q11: Não | R11: Não | S11: Não iniciado | T11: Não iniciado
A12: {=IFERROR(TEXT(INDEX(Base!E:E,MATCH(B12,Base!A:A,0)),"mm.dd.yyyy"),"mm.dd.yyyy")} -> mm.dd.yyyy | C12: {=IFERROR(INDEX(Base!I:I,MATCH(B12,Base!A:A,0)),"Nome do Cliente")} -> Nome do Cliente | D12: {=IFERROR(INDEX(Base!F:F,MATCH(B12,Base!A:A,0)),"Tipo do serv.")} -> Tipo do serv. | E12: {=IFERROR(INDEX(Base!G:G,MATCH(B12,Base!A:A,0)),"Modelo da Cond.")} -> Modelo da Cond. | F12: {=IFERROR(INDEX(Base!H:H,MATCH(B12,Base!A:A,0)),"N° Serial")} -> N° Serial | G12: FALSE | I12: Não | J12: Não | K12: Não | L12: Não | M12: FALSE | O12: Não | P12: Não | Q12: Não | R12: Não | S12: Não iniciado | T12: Não iniciado
A13: {=IFERROR(TEXT(INDEX(Base!E:E,MATCH(B13,Base!A:A,0)),"mm.dd.yyyy"),"mm.dd.yyyy")} -> mm.dd.yyyy | C13: {=IFERROR(INDEX(Base!I:I,MATCH(B13,Base!A:A,0)),"Nome do Cliente")} -> Nome do Cliente | D13: {=IFERROR(INDEX(Base!F:F,MATCH(B13,Base!A:A,0)),"Tipo do serv.")} -> Tipo do serv. | E13: {=IFERROR(INDEX(Base!G:G,MATCH(B13,Base!A:A,0)),"Modelo da Cond.")} -> Modelo da Cond. | F13: {=IFERROR(INDEX(Base!H:H,MATCH(B13,Base!A:A,0)),"N° Serial")} -> N° Serial | G13: FALSE | I13: Não | J13: Não | K13: Não | L13: Não | M13: FALSE | O13: Não | P13: Não | Q13: Não | R13: Não | S13: Não iniciado | T13: Não iniciado
A14: {=IFERROR(TEXT(INDEX(Base!E:E,MATCH(B14,Base!A:A,0)),"mm.dd.yyyy"),"mm.dd.yyyy")} -> mm.dd.yyyy | C14: {=IFERROR(INDEX(Base!I:I,MATCH(B14,Base!A:A,0)),"Nome do Cliente")} -> Nome do Cliente | D14: {=IFERROR(INDEX(Base!F:F,MATCH(B14,Base!A:A,0)),"Tipo do serv.")} -> Tipo do serv. | E14: {=IFERROR(INDEX(Base!G:G,MATCH(B14,Base!A:A,0)),"Modelo da Cond.")} -> Modelo da Cond. | F14: {=IFERROR(INDEX(Base!H:H,MATCH(B14,Base!A:A,0)),"N° Serial")} -> N° Serial | G14: FALSE | I14: Não | J14: Não | K14: Não | L14: Não | M14: FALSE | O14: Não | P14: Não | Q14: Não | R14: Não | S14: Não iniciado | T14: Não iniciado
A15: {=IFERROR(TEXT(INDEX(Base!E:E,MATCH(B15,Base!A:A,0)),"mm.dd.yyyy"),"mm.dd.yyyy")} -> mm.dd.yyyy | C15: {=IFERROR(INDEX(Base!I:I,MATCH(B15,Base!A:A,0)),"Nome do Cliente")} -> Nome do Cliente | D15: {=IFERROR(INDEX(Base!F:F,MATCH(B15,Base!A:A,0)),"Tipo do serv.")} -> Tipo do serv. | E15: {=IFERROR(INDEX(Base!G:G,MATCH(B15,Base!A:A,0)),"Modelo da Cond.")} -> Modelo da Cond. | F15: {=IFERROR(INDEX(Base!H:H,MATCH(B15,Base!A:A,0)),"N° Serial")} -> N° Serial | G15: FALSE | I15: Não | J15: Não | K15: Não | L15: Não | M15: FALSE | O15: Não | P15: Não | Q15: Não | R15: Não
